INFO 2019-04-12 23:09:31,314 basehttp 124 "GET / HTTP/1.1" 200 1714
WARNING 2019-04-12 23:09:31,385 base 152 Not Found: /favicon.ico
WARNING 2019-04-12 23:09:31,386 basehttp 124 "GET /favicon.ico HTTP/1.1" 404 1969
INFO 2019-04-13 09:42:21,095 basehttp 124 "GET /image_codes/1 HTTP/1.1" 301 0
INFO 2019-04-13 09:42:21,259 basehttp 124 "GET /image_codes/1/ HTTP/1.1" 200 3106
INFO 2019-04-13 09:44:26,790 basehttp 124 "GET /image_codes/2/ HTTP/1.1" 200 3233
INFO 2019-04-13 10:25:15,801 basehttp 124 "GET /image_codes/2/ HTTP/1.1" 200 3122
INFO 2019-04-13 10:25:39,262 basehttp 124 "GET /image_codes/3/ HTTP/1.1" 200 3332
INFO 2019-04-13 10:25:40,869 basehttp 124 "GET /image_codes/3/ HTTP/1.1" 200 3365
INFO 2019-04-13 10:26:02,149 basehttp 124 "GET /image_codes/3/ HTTP/1.1" 200 3503
INFO 2019-04-13 10:26:02,666 basehttp 124 "GET /image_codes/3/ HTTP/1.1" 200 2734
INFO 2019-04-13 10:26:02,913 basehttp 124 "GET /image_codes/3/ HTTP/1.1" 200 3423
INFO 2019-04-13 10:26:03,201 basehttp 124 "GET /image_codes/3/ HTTP/1.1" 200 3348
WARNING 2019-04-13 11:04:44,818 base 152 Not Found: /image_codes/
WARNING 2019-04-13 11:04:44,819 basehttp 124 "GET /image_codes/ HTTP/1.1" 404 2162
WARNING 2019-04-13 11:04:55,406 base 152 Not Found: /image_codes/3/
WARNING 2019-04-13 11:04:55,407 basehttp 124 "GET /image_codes/3/ HTTP/1.1" 404 2168
WARNING 2019-04-13 11:04:58,078 base 152 Not Found: /image_codes/3/
WARNING 2019-04-13 11:04:58,079 basehttp 124 "GET /image_codes/3/ HTTP/1.1" 404 2168
WARNING 2019-04-13 11:05:01,946 base 152 Not Found: /image_codes/3/
WARNING 2019-04-13 11:05:01,946 basehttp 124 "GET /image_codes/3/ HTTP/1.1" 404 2168
WARNING 2019-04-13 11:05:02,206 base 152 Not Found: /image_codes/3/
WARNING 2019-04-13 11:05:02,207 basehttp 124 "GET /image_codes/3/ HTTP/1.1" 404 2168
WARNING 2019-04-13 11:05:02,429 base 152 Not Found: /image_codes/3/
WARNING 2019-04-13 11:05:02,430 basehttp 124 "GET /image_codes/3/ HTTP/1.1" 404 2168
WARNING 2019-04-13 11:05:02,615 base 152 Not Found: /image_codes/3/
WARNING 2019-04-13 11:05:02,616 basehttp 124 "GET /image_codes/3/ HTTP/1.1" 404 2168
WARNING 2019-04-13 11:05:55,717 base 152 Not Found: /image_codes/5
WARNING 2019-04-13 11:05:55,719 basehttp 124 "GET /image_codes/5 HTTP/1.1" 404 2165
WARNING 2019-04-13 11:06:02,152 base 152 Not Found: /image_codes/5/
WARNING 2019-04-13 11:06:02,153 basehttp 124 "GET /image_codes/5/ HTTP/1.1" 404 2168
WARNING 2019-04-13 11:08:01,859 base 152 Not Found: /
WARNING 2019-04-13 11:08:01,860 basehttp 124 "GET / HTTP/1.1" 404 2108
WARNING 2019-04-13 11:08:04,297 base 152 Not Found: /
WARNING 2019-04-13 11:08:04,298 basehttp 124 "GET / HTTP/1.1" 404 2108
WARNING 2019-04-13 11:08:29,407 base 152 Not Found: /image_codes
WARNING 2019-04-13 11:08:29,408 basehttp 124 "GET /image_codes HTTP/1.1" 404 2159
WARNING 2019-04-13 11:08:35,949 base 152 Not Found: /image_codes/3/
WARNING 2019-04-13 11:08:35,950 basehttp 124 "GET /image_codes/3/ HTTP/1.1" 404 2168
WARNING 2019-04-13 11:08:41,990 base 152 Not Found: /image_codes/4
WARNING 2019-04-13 11:08:41,992 basehttp 124 "GET /image_codes/4 HTTP/1.1" 404 2165
WARNING 2019-04-13 11:08:46,343 base 152 Not Found: /image_codes/4/
WARNING 2019-04-13 11:08:46,345 basehttp 124 "GET /image_codes/4/ HTTP/1.1" 404 2168
INFO 2019-04-13 11:09:21,116 basehttp 124 "GET /image_codes/4/ HTTP/1.1" 200 3243
INFO 2019-04-13 11:09:22,586 basehttp 124 "GET /image_codes/4/ HTTP/1.1" 200 3080
WARNING 2019-04-13 11:09:35,995 base 152 Not Found: /image_codes/ijioj
WARNING 2019-04-13 11:09:35,996 basehttp 124 "GET /image_codes/ijioj HTTP/1.1" 404 2177
INFO 2019-04-13 11:12:08,001 basehttp 124 "GET /image_codes/ijioj HTTP/1.1" 301 0
INFO 2019-04-13 11:12:08,022 basehttp 124 "GET /image_codes/ijioj/ HTTP/1.1" 200 3329
WARNING 2019-04-13 12:45:05,181 base 152 Not Found: /mobiles/16602190828/count/
WARNING 2019-04-13 12:45:05,182 basehttp 124 "GET /mobiles/16602190828/count/ HTTP/1.1" 404 2204
WARNING 2019-04-13 12:50:26,419 base 152 Not Found: /mobiles/16602190828/count/
WARNING 2019-04-13 12:50:26,420 basehttp 124 "GET /mobiles/16602190828/count/ HTTP/1.1" 404 2204
WARNING 2019-04-13 12:50:26,555 base 152 Not Found: /mobiles/16602190828/count/
WARNING 2019-04-13 12:50:26,557 basehttp 124 "GET /mobiles/16602190828/count/ HTTP/1.1" 404 2204
INFO 2019-04-13 12:50:26,559 views 64 短信验证码为: 774889
ERROR 2019-04-13 12:50:27,112 exception 135 Internal Server Error: /sms_codes/16602190828/
Traceback (most recent call last):
  File "F:\python\lib\site-packages\rest_framework\views.py", line 492, in dispatch
    response = handler(request, *args, **kwargs)
  File "G:\python\my_object\shop_store\shoping_store\shoping_store\apps\verifications\views.py", line 94, in get
    from celery_tasks.sms.tasks import send_sms_code
  File "G:\python\my_object\shop_store\shoping_store\celery_tasks\sms\tasks.py", line 3, in <module>
    from .yuntongxun.sms import CCP
  File "G:\python\my_object\shop_store\shoping_store\celery_tasks\sms\yuntongxun\sms.py", line 3, in <module>
    from info.libs.yuntongxun.CCPRestSDK import REST
ModuleNotFoundError: No module named 'info'

During handling of the above exception, another exception occurred:

Traceback (most recent call last):
  File "F:\python\lib\site-packages\rest_framework\settings.py", line 183, in import_from_string
    module = import_module(module_path)
  File "F:\python\lib\importlib\__init__.py", line 126, in import_module
    return _bootstrap._gcd_import(name[level:], package, level)
  File "<frozen importlib._bootstrap>", line 994, in _gcd_import
  File "<frozen importlib._bootstrap>", line 971, in _find_and_load
  File "<frozen importlib._bootstrap>", line 941, in _find_and_load_unlocked
  File "<frozen importlib._bootstrap>", line 219, in _call_with_frames_removed
  File "<frozen importlib._bootstrap>", line 994, in _gcd_import
  File "<frozen importlib._bootstrap>", line 971, in _find_and_load
  File "<frozen importlib._bootstrap>", line 941, in _find_and_load_unlocked
  File "<frozen importlib._bootstrap>", line 219, in _call_with_frames_removed
  File "<frozen importlib._bootstrap>", line 994, in _gcd_import
  File "<frozen importlib._bootstrap>", line 971, in _find_and_load
  File "<frozen importlib._bootstrap>", line 953, in _find_and_load_unlocked
ModuleNotFoundError: No module named 'mei_shop_web'

During handling of the above exception, another exception occurred:

Traceback (most recent call last):
  File "F:\python\lib\site-packages\django\core\handlers\exception.py", line 41, in inner
    response = get_response(request)
  File "F:\python\lib\site-packages\django\core\handlers\base.py", line 187, in _get_response
    response = self.process_exception_by_middleware(e, request)
  File "F:\python\lib\site-packages\django\core\handlers\base.py", line 185, in _get_response
    response = wrapped_callback(request, *callback_args, **callback_kwargs)
  File "F:\python\lib\site-packages\django\views\decorators\csrf.py", line 58, in wrapped_view
    return view_func(*args, **kwargs)
  File "F:\python\lib\site-packages\django\views\generic\base.py", line 68, in view
    return self.dispatch(request, *args, **kwargs)
  File "F:\python\lib\site-packages\rest_framework\views.py", line 495, in dispatch
    response = self.handle_exception(exc)
  File "F:\python\lib\site-packages\rest_framework\views.py", line 449, in handle_exception
    exception_handler = self.get_exception_handler()
  File "F:\python\lib\site-packages\rest_framework\views.py", line 300, in get_exception_handler
    return self.settings.EXCEPTION_HANDLER
  File "F:\python\lib\site-packages\rest_framework\settings.py", line 227, in __getattr__
    val = perform_import(val, attr)
  File "F:\python\lib\site-packages\rest_framework\settings.py", line 170, in perform_import
    return import_from_string(val, setting_name)
  File "F:\python\lib\site-packages\rest_framework\settings.py", line 187, in import_from_string
    raise ImportError(msg)
ImportError: Could not import 'mei_shop_web.utils.exceptions.handler_excption' for API setting 'EXCEPTION_HANDLER'. ModuleNotFoundError: No module named 'mei_shop_web'.
ERROR 2019-04-13 12:50:27,491 basehttp 124 "GET /sms_codes/16602190828/ HTTP/1.1" 500 138858
WARNING 2019-04-13 12:52:35,100 base 152 Not Found: /mobiles/16602190828/count/
WARNING 2019-04-13 12:52:35,101 basehttp 124 "GET /mobiles/16602190828/count/ HTTP/1.1" 404 2204
WARNING 2019-04-13 12:52:35,200 base 152 Not Found: /mobiles/16602190828/count/
WARNING 2019-04-13 12:52:35,203 basehttp 124 "GET /mobiles/16602190828/count/ HTTP/1.1" 404 2204
INFO 2019-04-13 12:52:35,204 views 64 短信验证码为: 544776
ERROR 2019-04-13 12:52:35,651 exception 135 Internal Server Error: /sms_codes/16602190828/
Traceback (most recent call last):
  File "F:\python\lib\site-packages\rest_framework\views.py", line 492, in dispatch
    response = handler(request, *args, **kwargs)
  File "G:\python\my_object\shop_store\shoping_store\shoping_store\apps\verifications\views.py", line 94, in get
    from celery_tasks.sms.tasks import send_sms_code
  File "G:\python\my_object\shop_store\shoping_store\celery_tasks\sms\tasks.py", line 3, in <module>
    from .yuntongxun.sms import CCP
  File "G:\python\my_object\shop_store\shoping_store\celery_tasks\sms\yuntongxun\sms.py", line 3, in <module>
    from info.libs.yuntongxun.CCPRestSDK import REST
ModuleNotFoundError: No module named 'info'

During handling of the above exception, another exception occurred:

Traceback (most recent call last):
  File "F:\python\lib\site-packages\rest_framework\settings.py", line 183, in import_from_string
    module = import_module(module_path)
  File "F:\python\lib\importlib\__init__.py", line 126, in import_module
    return _bootstrap._gcd_import(name[level:], package, level)
  File "<frozen importlib._bootstrap>", line 994, in _gcd_import
  File "<frozen importlib._bootstrap>", line 971, in _find_and_load
  File "<frozen importlib._bootstrap>", line 941, in _find_and_load_unlocked
  File "<frozen importlib._bootstrap>", line 219, in _call_with_frames_removed
  File "<frozen importlib._bootstrap>", line 994, in _gcd_import
  File "<frozen importlib._bootstrap>", line 971, in _find_and_load
  File "<frozen importlib._bootstrap>", line 941, in _find_and_load_unlocked
  File "<frozen importlib._bootstrap>", line 219, in _call_with_frames_removed
  File "<frozen importlib._bootstrap>", line 994, in _gcd_import
  File "<frozen importlib._bootstrap>", line 971, in _find_and_load
  File "<frozen importlib._bootstrap>", line 953, in _find_and_load_unlocked
ModuleNotFoundError: No module named 'mei_shop_web'

During handling of the above exception, another exception occurred:

Traceback (most recent call last):
  File "F:\python\lib\site-packages\django\core\handlers\exception.py", line 41, in inner
    response = get_response(request)
  File "F:\python\lib\site-packages\django\core\handlers\base.py", line 187, in _get_response
    response = self.process_exception_by_middleware(e, request)
  File "F:\python\lib\site-packages\django\core\handlers\base.py", line 185, in _get_response
    response = wrapped_callback(request, *callback_args, **callback_kwargs)
  File "F:\python\lib\site-packages\django\views\decorators\csrf.py", line 58, in wrapped_view
    return view_func(*args, **kwargs)
  File "F:\python\lib\site-packages\django\views\generic\base.py", line 68, in view
    return self.dispatch(request, *args, **kwargs)
  File "F:\python\lib\site-packages\rest_framework\views.py", line 495, in dispatch
    response = self.handle_exception(exc)
  File "F:\python\lib\site-packages\rest_framework\views.py", line 449, in handle_exception
    exception_handler = self.get_exception_handler()
  File "F:\python\lib\site-packages\rest_framework\views.py", line 300, in get_exception_handler
    return self.settings.EXCEPTION_HANDLER
  File "F:\python\lib\site-packages\rest_framework\settings.py", line 227, in __getattr__
    val = perform_import(val, attr)
  File "F:\python\lib\site-packages\rest_framework\settings.py", line 170, in perform_import
    return import_from_string(val, setting_name)
  File "F:\python\lib\site-packages\rest_framework\settings.py", line 187, in import_from_string
    raise ImportError(msg)
ImportError: Could not import 'mei_shop_web.utils.exceptions.handler_excption' for API setting 'EXCEPTION_HANDLER'. ModuleNotFoundError: No module named 'mei_shop_web'.
ERROR 2019-04-13 12:52:35,879 basehttp 124 "GET /sms_codes/16602190828/ HTTP/1.1" 500 138858
WARNING 2019-04-13 14:18:57,197 base 152 Not Found: /image_codes/2/
WARNING 2019-04-13 14:18:57,198 basehttp 124 "GET /image_codes/2/ HTTP/1.1" 404 2713
ERROR 2019-04-13 14:19:45,970 exception 135 Internal Server Error: /users/
Traceback (most recent call last):
  File "F:\python\lib\site-packages\rest_framework\views.py", line 492, in dispatch
    response = handler(request, *args, **kwargs)
  File "F:\python\lib\site-packages\rest_framework\views.py", line 169, in http_method_not_allowed
    raise exceptions.MethodNotAllowed(request.method)
rest_framework.exceptions.MethodNotAllowed: 方法 “GET” 不被允许。

During handling of the above exception, another exception occurred:

Traceback (most recent call last):
  File "F:\python\lib\site-packages\django\core\handlers\exception.py", line 41, in inner
    response = get_response(request)
  File "F:\python\lib\site-packages\django\core\handlers\base.py", line 187, in _get_response
    response = self.process_exception_by_middleware(e, request)
  File "F:\python\lib\site-packages\django\core\handlers\base.py", line 185, in _get_response
    response = wrapped_callback(request, *callback_args, **callback_kwargs)
  File "F:\python\lib\site-packages\django\views\decorators\csrf.py", line 58, in wrapped_view
    return view_func(*args, **kwargs)
  File "F:\python\lib\site-packages\django\views\generic\base.py", line 68, in view
    return self.dispatch(request, *args, **kwargs)
  File "F:\python\lib\site-packages\rest_framework\views.py", line 495, in dispatch
    response = self.handle_exception(exc)
  File "F:\python\lib\site-packages\rest_framework\views.py", line 452, in handle_exception
    response = exception_handler(exc, context)
  File "G:\python\my_object\shop_store\shoping_store\shoping_store\utils\exceptions.py", line 20, in handler_excption
    response=drf_exception_handler(exc,context)
TypeError: 'module' object is not callable
ERROR 2019-04-13 14:19:46,216 basehttp 124 "GET /users/ HTTP/1.1" 500 96677
ERROR 2019-04-13 14:27:44,607 exception 135 Internal Server Error: /users/
Traceback (most recent call last):
  File "F:\python\lib\site-packages\rest_framework\views.py", line 492, in dispatch
    response = handler(request, *args, **kwargs)
  File "F:\python\lib\site-packages\rest_framework\views.py", line 169, in http_method_not_allowed
    raise exceptions.MethodNotAllowed(request.method)
rest_framework.exceptions.MethodNotAllowed: 方法 “GET” 不被允许。

During handling of the above exception, another exception occurred:

Traceback (most recent call last):
  File "F:\python\lib\site-packages\django\core\handlers\exception.py", line 41, in inner
    response = get_response(request)
  File "F:\python\lib\site-packages\django\core\handlers\base.py", line 187, in _get_response
    response = self.process_exception_by_middleware(e, request)
  File "F:\python\lib\site-packages\django\core\handlers\base.py", line 185, in _get_response
    response = wrapped_callback(request, *callback_args, **callback_kwargs)
  File "F:\python\lib\site-packages\django\views\decorators\csrf.py", line 58, in wrapped_view
    return view_func(*args, **kwargs)
  File "F:\python\lib\site-packages\django\views\generic\base.py", line 68, in view
    return self.dispatch(request, *args, **kwargs)
  File "F:\python\lib\site-packages\rest_framework\views.py", line 495, in dispatch
    response = self.handle_exception(exc)
  File "F:\python\lib\site-packages\rest_framework\views.py", line 452, in handle_exception
    response = exception_handler(exc, context)
  File "G:\python\my_object\shop_store\shoping_store\shoping_store\utils\exceptions.py", line 20, in handler_excption
    response=drf_exception_handler(exc,context)
TypeError: 'module' object is not callable
ERROR 2019-04-13 14:27:44,819 basehttp 124 "GET /users/ HTTP/1.1" 500 96812
ERROR 2019-04-13 14:28:04,015 exception 135 Internal Server Error: /user/
Traceback (most recent call last):
  File "F:\python\lib\site-packages\rest_framework\views.py", line 483, in dispatch
    self.initial(request, *args, **kwargs)
  File "F:\python\lib\site-packages\rest_framework\views.py", line 401, in initial
    self.check_permissions(request)
  File "F:\python\lib\site-packages\rest_framework\views.py", line 336, in check_permissions
    request, message=getattr(permission, 'message', None)
  File "F:\python\lib\site-packages\rest_framework\views.py", line 176, in permission_denied
    raise exceptions.NotAuthenticated()
rest_framework.exceptions.NotAuthenticated: 身份认证信息未提供。

During handling of the above exception, another exception occurred:

Traceback (most recent call last):
  File "F:\python\lib\site-packages\django\core\handlers\exception.py", line 41, in inner
    response = get_response(request)
  File "F:\python\lib\site-packages\django\core\handlers\base.py", line 187, in _get_response
    response = self.process_exception_by_middleware(e, request)
  File "F:\python\lib\site-packages\django\core\handlers\base.py", line 185, in _get_response
    response = wrapped_callback(request, *callback_args, **callback_kwargs)
  File "F:\python\lib\site-packages\django\views\decorators\csrf.py", line 58, in wrapped_view
    return view_func(*args, **kwargs)
  File "F:\python\lib\site-packages\django\views\generic\base.py", line 68, in view
    return self.dispatch(request, *args, **kwargs)
  File "F:\python\lib\site-packages\rest_framework\views.py", line 495, in dispatch
    response = self.handle_exception(exc)
  File "F:\python\lib\site-packages\rest_framework\views.py", line 452, in handle_exception
    response = exception_handler(exc, context)
  File "G:\python\my_object\shop_store\shoping_store\shoping_store\utils\exceptions.py", line 20, in handler_excption
    response=drf_exception_handler(exc,context)
TypeError: 'module' object is not callable
ERROR 2019-04-13 14:28:04,084 basehttp 124 "GET /user/ HTTP/1.1" 500 105131
INFO 2019-04-13 14:29:21,509 basehttp 124 "GET /usernames/apple/count/ HTTP/1.1" 200 30
INFO 2019-04-13 14:29:29,444 basehttp 124 "GET /mobiles/16602190828/count/ HTTP/1.1" 200 34
INFO 2019-04-13 14:29:29,539 views 64 短信验证码为: 672920
INFO 2019-04-13 14:29:29,561 basehttp 124 "GET /mobiles/16602190828/count/ HTTP/1.1" 200 34
ERROR 2019-04-13 14:29:30,003 exception 135 Internal Server Error: /sms_codes/16602190828/
Traceback (most recent call last):
  File "F:\python\lib\site-packages\rest_framework\views.py", line 492, in dispatch
    response = handler(request, *args, **kwargs)
  File "G:\python\my_object\shop_store\shoping_store\shoping_store\apps\verifications\views.py", line 94, in get
    from celery_tasks.sms.tasks import send_sms_code
  File "G:\python\my_object\shop_store\shoping_store\celery_tasks\sms\tasks.py", line 3, in <module>
    from .yuntongxun.sms import CCP
  File "G:\python\my_object\shop_store\shoping_store\celery_tasks\sms\yuntongxun\sms.py", line 3, in <module>
    from info.libs.yuntongxun.CCPRestSDK import REST
ModuleNotFoundError: No module named 'info'

During handling of the above exception, another exception occurred:

Traceback (most recent call last):
  File "F:\python\lib\site-packages\django\core\handlers\exception.py", line 41, in inner
    response = get_response(request)
  File "F:\python\lib\site-packages\django\core\handlers\base.py", line 187, in _get_response
    response = self.process_exception_by_middleware(e, request)
  File "F:\python\lib\site-packages\django\core\handlers\base.py", line 185, in _get_response
    response = wrapped_callback(request, *callback_args, **callback_kwargs)
  File "F:\python\lib\site-packages\django\views\decorators\csrf.py", line 58, in wrapped_view
    return view_func(*args, **kwargs)
  File "F:\python\lib\site-packages\django\views\generic\base.py", line 68, in view
    return self.dispatch(request, *args, **kwargs)
  File "F:\python\lib\site-packages\rest_framework\views.py", line 495, in dispatch
    response = self.handle_exception(exc)
  File "F:\python\lib\site-packages\rest_framework\views.py", line 452, in handle_exception
    response = exception_handler(exc, context)
  File "G:\python\my_object\shop_store\shoping_store\shoping_store\utils\exceptions.py", line 20, in handler_excption
    response=drf_exception_handler(exc,context)
TypeError: 'module' object is not callable
ERROR 2019-04-13 14:29:30,051 basehttp 124 "GET /sms_codes/16602190828/ HTTP/1.1" 500 119578
